<?xml version="1.0" ?>

<robot name="joebot" xmlns:xacro="http://www.ros.org/wiki/xacro">
	<link name="world" />
	<joint name="fixed" type="fixed">
		<parent link="world" />
		<child link="base_link" />
	</joint>
	
	<link name="base_link">
		<inertial>
			<mass value="1000" />
			<origin xyz="0 0 0" rpy="0 0 0" />
			<inertia ixx="1" ixy="0" ixz="0" iyy="1" iyz="0" izz="1" />
		</inertial>
		
		<collision>
			<origin xyz="0 0 0" rpy="0 0 0" />
			<geometry>
				<box size="0.2 0.2 0.75" />
			</geometry>
		</collision>
		
		<visual>
			<origin xyz="0 0 0" rpy="0 0 0" />
			<geometry>
				<box size="0.2 0.2 0.75" />
			</geometry>
		</visual>
	</link>
	
	<joint name="base_link__link_1" type="continuous">
		<axis xyz="0 0 1" />
		<limit effort="10.0" velocity="0.5" />
		<origin xyz="0 0 0.375" rpy="0 0 0" />
		<parent link="base_link" />
		<child link="link_1" />
	</joint>

	<transmission name="trans_base_link__link_1">
		<type>transmission_interface/SimpleTransmission</type>
		<joint name="base_link__link_1">
			<hardwareInterface>hardware_interface/EffortJointInterface</hardwareInterface>
		</joint>
		<actuator name="motor_base_link__link_1">
			<hardwareInterface>hardware_interface/EffortJointInterface</hardwareInterface>
			<mechanicalReduction>1</mechanicalReduction>
		</actuator>
	</transmission>
	
	<link name="link_1">
		<inertial>
			<mass value="1" />
			<origin xyz="0 0 0" rpy="0 0 0" />
			<inertia ixx="1" ixy="0" ixz="0" iyy="1" iyz="0" izz="1" />
		</inertial>
		
		<collision>
			<origin xyz="0 0 0.125" rpy="0 0 0" />
			<geometry>
				<cylinder radius="0.09" length="0.25" />
			</geometry>
		</collision>
		
		<visual>
			<origin xyz="0 0 0.125" rpy="0 0 0" />
			<geometry>
				<cylinder radius="0.09" length="0.25" />
			</geometry>
		</visual>
	</link>

	<gazebo reference="link_1">
		<sensor type="camera" name="camera1">
			<pose>0.09 0 0.125 0 -0 0</pose>
			<camera name='__default__'>
				<horizontal_fov>0.5</horizontal_fov>
				<image>
					<width>320</width>
					<height>240</height>
				</image>
				<clip>
					<near>0.1</near>
					<far>100</far>
				</clip>
			</camera>

			<plugin name="gazebo_light_sensor_plugin" filename="libgazebo_light_sensor_plugin.so">
				<cameraName>camera</cameraName>
				<alwaysOn>true</alwaysOn>
				<updateRate>10</updateRate>
				<imageTopicName>rgb/image_raw</imageTopicName>
				<depthImageTopicName>depth/image_raw</depthImageTopicName>
				<pointCloudTopicName>depth/points</pointCloudTopicName>
				<cameraInfoTopicName>rgb/camera_info</cameraInfoTopicName>
				<depthImageCameraInfoTopicName>depth/camera_info</depthImageCameraInfoTopicName>
				<frameName>camera_depth_optical_frame</frameName>
				<baseline>0.1</baseline>
				<distortion_k1>0.0</distortion_k1>
				<distortion_k2>0.0</distortion_k2>
				<distortion_k3>0.0</distortion_k3>
				<distortion_t1>0.0</distortion_t1>
				<distortion_t2>0.0</distortion_t2>
				<pointCloudCutoff>0.4</pointCloudCutoff>
				<robotNamespace>/</robotNamespace>
			</plugin>

			<visualize>true</visualize>
		</sensor>
	</gazebo>

	<gazebo>
		<plugin name="gazebo_ros_control" filename="libgazebo_ros_control.so">
		</plugin>
	</gazebo>
</robot>
