<?xml version="1.0" ?>

<robot name="joebot" xmlns:xacro="http://www.ros.org/wiki/xacro">
	<link name="base_link">
		<visual>
			<origin xyz="0 0 0.375" rpy="0 0 0" />
			<geometry>
				<box size="0.2 0.2 0.75" />
			</geometry>
		</visual>
	</link>
	
	<joint name="base_link__link_1" type="revolute">
		<axis xyz="0 0 1" />
		<limit effort="1000.0" lower="-3.14" upper="3.14" velocity="0.5" />
		<origin xyz="0 0 0.75" />
		<parent link="base_link" />
		<child link="link_1" />
	</joint>
	
	<link name="link_1">
		<visual>
			<origin xyz="0 0 0.875" rpy="0 0 0" />
			<geometry>
				<cylinder radius="0.15" length="0.25" />
			</geometry>
		</visual>
	</link>
</robot>
